<?xml version="1.0" ?>
<!-- =================================================================================== -->
<!-- |    This document was autogenerated by xacro from nimbus.urdf.xacro              | -->
<!-- |    EDITING THIS FILE BY HAND IS NOT RECOMMENDED                                 | -->
<!-- =================================================================================== -->
<robot name="nimbus" xmlns:body="http://playerstage.sourceforge.net/gazebo/xmlschema/#body" xmlns:controller="http://playerstage.sourceforge.net/gazebo/xmlschema/#controller" xmlns:gazebo="http://playerstage.sourceforge.net/gazebo/xmlschema/#gz" xmlns:geom="http://playerstage.sourceforge.net/gazebo/xmlschema/#geom" xmlns:interface="http://playerstage.sourceforge.net/gazebo/xmlschema/#interface" xmlns:joint="http://playerstage.sourceforge.net/gazebo/xmlschema/#joint" xmlns:model="http://playerstage.sourceforge.net/gazebo/xmlschema/#model" xmlns:physics="http://playerstage.sourceforge.net/gazebo/xmlschema/#physics" xmlns:renderable="http://playerstage.sourceforge.net/gazebo/xmlschema/#renderable" xmlns:rendering="http://playerstage.sourceforge.net/gazebo/xmlschema/#rendering" xmlns:sensor="http://playerstage.sourceforge.net/gazebo/xmlschema/#sensor" xmlns:xacro="http://ros.org/wiki/xacro" xmlns:xi="http://www.w3.org/2001/XInclude">
  <!--
  Author: David Kent
  Very simplified arm model for use in self-subtraction of point clouds (significantly improves runtime)
-->
  --&gt;
  
  <!-- links      		mesh_no
   base           		0
   shoulder       		1
   arm            		2
   forearm        		3
   wrist          		4
   arm_mico       		5
   arm_half1 (7dof)		6
   arm_half2 (7dof)		7
   wrist_spherical_1  8
   wrist_spherical_2  9

   hand 3 finger  		55
   hand_2finger   		56
   finger_proximal		57
   finger_distal      58 
-->
  <!-- links      		mesh_no
   base           		0
   shoulder       		1
   arm            		2
   forearm        		3
   wrist          		4
   arm_mico       		5
   arm_half1 (7dof)		6
   arm_half2 (7dof)		7
   wrist_spherical_1  8
   wrist_spherical_2  9

   hand 3 finger  		55
   hand_2finger   		56
   finger_proximal		57
   finger_distal      58 
-->
  <!-- Import all Gazebo-customization elements -->
  <!--Used for conditional arguments for setting inertial parameters
        base 0, shoulder 1, arm 2, forearm 3, wrist 4, arm_mico 5,
        arm_half1 (7dof)	6, arm_half2 (7dof) 7, wrist_spherical_1  8, wrist_spherical_2  9
        fore_arm_mico 10,
        hand 3 finger 55, hand_2finger 56, finger_proximal 57, finger_distal 58 
    -->
  <!-- Xacro properties -->
  <!-- Xacro properties -->
  <!-- Parameterised in part by the values in turtlebot_properties.urdf.xacro -->
  <!-- Xacro properties -->
  <!-- Xacro properties -->
  <link name="table_base_link">
    <!--
    <visual>
      <geometry>
        <cylinder length="0.022" radius=".9144"/>
      </geometry>
      <origin rpy="0 0 0" xyz="0 0 -0.011" />
      <material name="tan">
        <color rgba="0.871 0.722 0.529 1" />
      </material>
    </visual>
    <collision>
      <geometry>
        <cylinder length="0.022" radius=".9144"/>
      </geometry>
      <origin rpy="0 0 0" xyz="0 0 -0.011" />
    </collision>
    -->
  </link>
  <xacro:nimbus_kinect parent="table_base_link">
    <origin rpy="0 0 0" xyz="0 0 0"/>
  </xacro:nimbus_kinect>
  <joint name="table_base_link_arm_mount_plate_link_joint" type="fixed">
    <parent link="table_base_link"/>
    <child link="arm_mount_plate_link"/>
    <origin rpy="0 0 0" xyz="0 0.0762 0"/>
  </joint>
  <link name="arm_mount_plate_link">
    <visual>
      <geometry>
        <box size="0.2032 0.1524 0.015875"/>
      </geometry>
      <origin rpy="0 0 0" xyz="0 0 0.0079375"/>
      <material name="dark-gray">
        <color rgba="0.2 0.2 0.2 1"/>
      </material>
    </visual>
    <collision>
      <geometry>
        <box size="0.2032 0.1524 0.015875"/>
      </geometry>
      <origin rpy="0 0 0" xyz="0 0 0.0079375"/>
    </collision>
  </link>
  <joint name="arm_mount_plate_link_arm_mount_beam_link_joint" type="fixed">
    <parent link="arm_mount_plate_link"/>
    <child link="arm_mount_beam_link"/>
    <origin rpy="0 0 3.14159265359" xyz="0 0 0"/>
  </joint>
  <link name="arm_mount_beam_link">
    <visual>
      <geometry>
        <box size="0.0396875 0.0396875 0.0889"/>
      </geometry>
      <origin rpy="0 0 0" xyz="0 0 0.04445"/>
      <material name="dark-gray"/>
    </visual>
    <collision>
      <geometry>
        <box size="0.0396875 0.0396875 0.0889"/>
      </geometry>
      <origin rpy="0 0 0" xyz="0 0 0.04445"/>
    </collision>
  </link>
  <!-- ros_control plugin -->
  <gazebo>
    <plugin filename="libgazebo_ros_control.so" name="gazebo_ros_control">
      <robotNamespace>j2s7s300</robotNamespace>
      <robotSimType>gazebo_ros_control/DefaultRobotHWSim</robotSimType>
    </plugin>
  </gazebo>
  <link name="j2s7s300_link_base">
    <visual>
      <geometry>
        <mesh filename="package://kinova_description/meshes/base.dae"/>
      </geometry>
      <material name="carbon_fiber">
        <color rgba="0.792156862745098 0.819607843137255 0.933333333333333 1"/>
      </material>
    </visual>
    <!-- Adding ring to the model -->
    <collision>
      <geometry>
        <mesh filename="package://kinova_description/meshes/base.dae"/>
      </geometry>
    </collision>
    <!-- base = 0 -->
    <inertial>
      <mass value="0.46784"/>
      <origin rpy="0 0 0" xyz="0 0 0.1255"/>
      <!-- z Axis -->
      <inertia ixx="0.000951270861568" ixy="0" ixz="0" iyy="0.000951270861568" iyz="0" izz="0.000374272"/>
      <!-- y Axis -->
      <!-- x Axis -->
    </inertial>
    <!-- shoulder = 1 -->
    <!-- arm = 2-->
    <!-- forearm = 3 -->
    <!-- wrist = 4 -->
    <!--arm_mico       		5 -->
    <!--   arm_half1 (7dof)		6 -->
    <!--   arm_half2 (7dof)		7 -->
    <!--   wrist_spherical_1  8 -->
    <!--   wrist_spherical_2  9 -->
    <!--   forearm_mico  10 -->
    <!-- hand 3 finger = 55 -->
    <!-- hand 2 finger = 56 -->
    <!-- finger_proximal = 57 -->
    <!-- finger_distal = 58 -->
  </link>
  <joint name="j2s7s300_joint_base" type="fixed">
    <parent link="arm_mount_beam_link"/>
    <child link="j2s7s300_link_base"/>
    <axis xyz="0 0 0"/>
    <limit effort="2000" lower="0" upper="0" velocity="1"/>
    <origin rpy="0 0 0" xyz="0 0 0"/>
    <dynamics damping="0.0" friction="0.0"/>
  </joint>
  <link name="j2s7s300_link_1">
    <visual>
      <geometry>
        <mesh filename="package://kinova_description/meshes/shoulder.dae"/>
      </geometry>
      <material name="carbon_fiber">
        <color rgba="0.792156862745098 0.819607843137255 0.933333333333333 1"/>
      </material>
    </visual>
    <!-- Adding ring to the model -->
    <visual>
      <geometry>
        <mesh filename="package://kinova_description/meshes/ring_big.STL"/>
      </geometry>
    </visual>
    <collision>
      <geometry>
        <mesh filename="package://kinova_description/meshes/shoulder.dae"/>
      </geometry>
    </collision>
    <!-- base = 0 -->
    <!-- shoulder = 1 -->
    <inertial>
      <mass value="0.7477"/>
      <origin xyz="0 -0.002 -0.0605"/>
      <!-- z Axis -->
      <inertia ixx="0.00152031725204" ixy="0" ixz="0" iyy="0.00152031725204" iyz="0" izz="0.00059816"/>
      <!-- y Axis -->
      <!-- x Axis -->
    </inertial>
    <!-- arm = 2-->
    <!-- forearm = 3 -->
    <!-- wrist = 4 -->
    <!--arm_mico       		5 -->
    <!--   arm_half1 (7dof)		6 -->
    <!--   arm_half2 (7dof)		7 -->
    <!--   wrist_spherical_1  8 -->
    <!--   wrist_spherical_2  9 -->
    <!--   forearm_mico  10 -->
    <!-- hand 3 finger = 55 -->
    <!-- hand 2 finger = 56 -->
    <!-- finger_proximal = 57 -->
    <!-- finger_distal = 58 -->
  </link>
  <joint name="j2s7s300_joint_1" type="continuous">
    <parent link="j2s7s300_link_base"/>
    <child link="j2s7s300_link_1"/>
    <axis xyz="0 0 1"/>
    <limit effort="2000" lower="-6.28318530718" upper="6.28318530718" velocity="1"/>
    <origin rpy="0 3.14159265359 0" xyz="0 0 0.15675"/>
    <dynamics damping="0.0" friction="0.0"/>
  </joint>
  <transmission name="j2s7s300_joint_1_trans">
    <type>transmission_interface/SimpleTransmission</type>
    <joint name="j2s7s300_joint_1">
      <hardwareInterface>EffortJointInterface</hardwareInterface>
    </joint>
    <actuator name="j2s7s300_joint_1_actuator">
      <hardwareInterface>EffortJointInterface</hardwareInterface>
      <mechanicalReduction>160</mechanicalReduction>
    </actuator>
  </transmission>
  <link name="j2s7s300_link_2">
    <visual>
      <geometry>
        <mesh filename="package://kinova_description/meshes/arm_half_1.dae"/>
      </geometry>
      <material name="carbon_fiber">
        <color rgba="0.792156862745098 0.819607843137255 0.933333333333333 1"/>
      </material>
    </visual>
    <!-- Adding ring to the model -->
    <visual>
      <geometry>
        <mesh filename="package://kinova_description/meshes/ring_big.STL"/>
      </geometry>
    </visual>
    <collision>
      <geometry>
        <mesh filename="package://kinova_description/meshes/arm_half_1.dae"/>
      </geometry>
    </collision>
    <!-- base = 0 -->
    <!-- shoulder = 1 -->
    <!-- arm = 2-->
    <!-- forearm = 3 -->
    <!-- wrist = 4 -->
    <!--arm_mico       		5 -->
    <!--   arm_half1 (7dof)		6 -->
    <inertial>
      <mass value="0.8447"/>
      <origin xyz="0 -0.103563213 0"/>
      <!-- z Axis -->
      <!-- y Axis -->
      <inertia ixx="0.00247073761701" ixy="0" ixz="0" iyy="0.000380115" iyz="0" izz="0.00247073761701"/>
      <!-- x Axis -->
    </inertial>
    <!--   arm_half2 (7dof)		7 -->
    <!--   wrist_spherical_1  8 -->
    <!--   wrist_spherical_2  9 -->
    <!--   forearm_mico  10 -->
    <!-- hand 3 finger = 55 -->
    <!-- hand 2 finger = 56 -->
    <!-- finger_proximal = 57 -->
    <!-- finger_distal = 58 -->
  </link>
  <joint name="j2s7s300_joint_2" type="revolute">
    <parent link="j2s7s300_link_1"/>
    <child link="j2s7s300_link_2"/>
    <axis xyz="0 0 1"/>
    <limit effort="2000" lower="0.523598775598" upper="5.75958653158" velocity="1"/>
    <origin rpy="-1.57079632679 0 3.14159265359" xyz="0 0.0016 -0.11875"/>
    <dynamics damping="0.0" friction="0.0"/>
  </joint>
  <transmission name="j2s7s300_joint_2_trans">
    <type>transmission_interface/SimpleTransmission</type>
    <joint name="j2s7s300_joint_2">
      <hardwareInterface>EffortJointInterface</hardwareInterface>
    </joint>
    <actuator name="j2s7s300_joint_2_actuator">
      <hardwareInterface>EffortJointInterface</hardwareInterface>
      <mechanicalReduction>160</mechanicalReduction>
    </actuator>
  </transmission>
  <link name="j2s7s300_link_3">
    <visual>
      <geometry>
        <mesh filename="package://kinova_description/meshes/arm_half_2.dae"/>
      </geometry>
      <material name="carbon_fiber">
        <color rgba="0.792156862745098 0.819607843137255 0.933333333333333 1"/>
      </material>
    </visual>
    <!-- Adding ring to the model -->
    <visual>
      <geometry>
        <mesh filename="package://kinova_description/meshes/ring_big.STL"/>
      </geometry>
    </visual>
    <collision>
      <geometry>
        <mesh filename="package://kinova_description/meshes/arm_half_2.dae"/>
      </geometry>
    </collision>
    <!-- base = 0 -->
    <!-- shoulder = 1 -->
    <!-- arm = 2-->
    <!-- forearm = 3 -->
    <!-- wrist = 4 -->
    <!--arm_mico       		5 -->
    <!--   arm_half1 (7dof)		6 -->
    <!--   arm_half2 (7dof)		7 -->
    <inertial>
      <mass value="0.8447"/>
      <origin xyz="0 0 -0.1022447445"/>
      <!-- z Axis -->
      <inertia ixx="0.00247073761701" ixy="0" ixz="0" iyy="0.00247073761701" iyz="0" izz="0.000380115"/>
      <!-- y Axis -->
      <!-- x Axis -->
    </inertial>
    <!--   wrist_spherical_1  8 -->
    <!--   wrist_spherical_2  9 -->
    <!--   forearm_mico  10 -->
    <!-- hand 3 finger = 55 -->
    <!-- hand 2 finger = 56 -->
    <!-- finger_proximal = 57 -->
    <!-- finger_distal = 58 -->
  </link>
  <joint name="j2s7s300_joint_3" type="continuous">
    <parent link="j2s7s300_link_2"/>
    <child link="j2s7s300_link_3"/>
    <axis xyz="0 0 1"/>
    <limit effort="2000" lower="-6.28318530718" upper="6.28318530718" velocity="1"/>
    <origin rpy="-1.57079632679 0 0" xyz="0 -0.205 0"/>
    <dynamics damping="0.0" friction="0.0"/>
  </joint>
  <transmission name="j2s7s300_joint_3_trans">
    <type>transmission_interface/SimpleTransmission</type>
    <joint name="j2s7s300_joint_3">
      <hardwareInterface>EffortJointInterface</hardwareInterface>
    </joint>
    <actuator name="j2s7s300_joint_3_actuator">
      <hardwareInterface>EffortJointInterface</hardwareInterface>
      <mechanicalReduction>160</mechanicalReduction>
    </actuator>
  </transmission>
  <link name="j2s7s300_link_4">
    <visual>
      <geometry>
        <mesh filename="package://kinova_description/meshes/forearm.dae"/>
      </geometry>
      <material name="carbon_fiber">
        <color rgba="0.792156862745098 0.819607843137255 0.933333333333333 1"/>
      </material>
    </visual>
    <!-- Adding ring to the model -->
    <visual>
      <geometry>
        <mesh filename="package://kinova_description/meshes/ring_small.STL"/>
      </geometry>
    </visual>
    <collision>
      <geometry>
        <mesh filename="package://kinova_description/meshes/forearm.dae"/>
      </geometry>
    </collision>
    <!-- base = 0 -->
    <!-- shoulder = 1 -->
    <!-- arm = 2-->
    <!-- forearm = 3 -->
    <inertial>
      <mass value="0.6763"/>
      <origin xyz="0 0.081 -0.0086"/>
      <!-- z Axis -->
      <!-- y Axis -->
      <inertia ixx="0.00142022431908" ixy="0" ixz="0" iyy="0.000304335" iyz="0" izz="0.00142022431908"/>
      <!-- x Axis -->
    </inertial>
    <!-- wrist = 4 -->
    <!--arm_mico       		5 -->
    <!--   arm_half1 (7dof)		6 -->
    <!--   arm_half2 (7dof)		7 -->
    <!--   wrist_spherical_1  8 -->
    <!--   wrist_spherical_2  9 -->
    <!--   forearm_mico  10 -->
    <!-- hand 3 finger = 55 -->
    <!-- hand 2 finger = 56 -->
    <!-- finger_proximal = 57 -->
    <!-- finger_distal = 58 -->
  </link>
  <joint name="j2s7s300_joint_4" type="revolute">
    <parent link="j2s7s300_link_3"/>
    <child link="j2s7s300_link_4"/>
    <axis xyz="0 0 1"/>
    <limit effort="2000" lower="0.523598775598" upper="5.75958653158" velocity="1"/>
    <origin rpy="1.57079632679 0 3.14159265359" xyz="0 0 -0.205"/>
    <dynamics damping="0.0" friction="0.0"/>
  </joint>
  <transmission name="j2s7s300_joint_4_trans">
    <type>transmission_interface/SimpleTransmission</type>
    <joint name="j2s7s300_joint_4">
      <hardwareInterface>EffortJointInterface</hardwareInterface>
    </joint>
    <actuator name="j2s7s300_joint_4_actuator">
      <hardwareInterface>EffortJointInterface</hardwareInterface>
      <mechanicalReduction>160</mechanicalReduction>
    </actuator>
  </transmission>
  <link name="j2s7s300_link_5">
    <visual>
      <geometry>
        <mesh filename="package://kinova_description/meshes/wrist_spherical_1.dae"/>
      </geometry>
      <material name="carbon_fiber">
        <color rgba="0.792156862745098 0.819607843137255 0.933333333333333 1"/>
      </material>
    </visual>
    <!-- Adding ring to the model -->
    <visual>
      <geometry>
        <mesh filename="package://kinova_description/meshes/ring_small.STL"/>
      </geometry>
    </visual>
    <collision>
      <geometry>
        <mesh filename="package://kinova_description/meshes/wrist_spherical_1.dae"/>
      </geometry>
    </collision>
    <!-- base = 0 -->
    <!-- shoulder = 1 -->
    <!-- arm = 2-->
    <!-- forearm = 3 -->
    <!-- wrist = 4 -->
    <!--arm_mico       		5 -->
    <!--   arm_half1 (7dof)		6 -->
    <!--   arm_half2 (7dof)		7 -->
    <!--   wrist_spherical_1  8 -->
    <inertial>
      <mass value="0.463"/>
      <origin xyz="0 0.0028848942 -0.0541932613"/>
      <!-- z Axis -->
      <inertia ixx="0.0004321316048" ixy="0" ixz="0" iyy="0.0004321316048" iyz="0" izz="9.26e-05"/>
      <!-- y Axis -->
      <!-- x Axis -->
    </inertial>
    <!--   wrist_spherical_2  9 -->
    <!--   forearm_mico  10 -->
    <!-- hand 3 finger = 55 -->
    <!-- hand 2 finger = 56 -->
    <!-- finger_proximal = 57 -->
    <!-- finger_distal = 58 -->
  </link>
  <joint name="j2s7s300_joint_5" type="continuous">
    <parent link="j2s7s300_link_4"/>
    <child link="j2s7s300_link_5"/>
    <axis xyz="0 0 1"/>
    <limit effort="2000" lower="-6.28318530718" upper="6.28318530718" velocity="1"/>
    <origin rpy="-1.57079632679 0 3.14159265359" xyz="0 0.2073 -0.0114"/>
    <dynamics damping="0.0" friction="0.0"/>
  </joint>
  <transmission name="j2s7s300_joint_5_trans">
    <type>transmission_interface/SimpleTransmission</type>
    <joint name="j2s7s300_joint_5">
      <hardwareInterface>EffortJointInterface</hardwareInterface>
    </joint>
    <actuator name="j2s7s300_joint_5_actuator">
      <hardwareInterface>EffortJointInterface</hardwareInterface>
      <mechanicalReduction>160</mechanicalReduction>
    </actuator>
  </transmission>
  <link name="j2s7s300_link_6">
    <visual>
      <geometry>
        <mesh filename="package://kinova_description/meshes/wrist_spherical_2.dae"/>
      </geometry>
      <material name="carbon_fiber">
        <color rgba="0.792156862745098 0.819607843137255 0.933333333333333 1"/>
      </material>
    </visual>
    <!-- Adding ring to the model -->
    <visual>
      <geometry>
        <mesh filename="package://kinova_description/meshes/ring_small.STL"/>
      </geometry>
    </visual>
    <collision>
      <geometry>
        <mesh filename="package://kinova_description/meshes/wrist_spherical_2.dae"/>
      </geometry>
    </collision>
    <!-- base = 0 -->
    <!-- shoulder = 1 -->
    <!-- arm = 2-->
    <!-- forearm = 3 -->
    <!-- wrist = 4 -->
    <!--arm_mico       		5 -->
    <!--   arm_half1 (7dof)		6 -->
    <!--   arm_half2 (7dof)		7 -->
    <!--   wrist_spherical_1  8 -->
    <!--   wrist_spherical_2  9 -->
    <inertial>
      <mass value="0.463"/>
      <origin xyz="0 0.0497208855 -0.0028562765"/>
      <!-- z Axis -->
      <!-- y Axis -->
      <inertia ixx="0.0004321316048" ixy="0" ixz="0" iyy="9.26e-05" iyz="0" izz="0.0004321316048"/>
      <!-- x Axis -->
    </inertial>
    <!--   forearm_mico  10 -->
    <!-- hand 3 finger = 55 -->
    <!-- hand 2 finger = 56 -->
    <!-- finger_proximal = 57 -->
    <!-- finger_distal = 58 -->
  </link>
  <joint name="j2s7s300_joint_6" type="revolute">
    <parent link="j2s7s300_link_5"/>
    <child link="j2s7s300_link_6"/>
    <axis xyz="0 0 1"/>
    <limit effort="2000" lower="0.523598775598" upper="5.75958653158" velocity="1"/>
    <origin rpy="1.57079632679 0 3.14159265359" xyz="0 0 -0.10375"/>
    <dynamics damping="0.0" friction="0.0"/>
  </joint>
  <transmission name="j2s7s300_joint_6_trans">
    <type>transmission_interface/SimpleTransmission</type>
    <joint name="j2s7s300_joint_6">
      <hardwareInterface>EffortJointInterface</hardwareInterface>
    </joint>
    <actuator name="j2s7s300_joint_6_actuator">
      <hardwareInterface>EffortJointInterface</hardwareInterface>
      <mechanicalReduction>160</mechanicalReduction>
    </actuator>
  </transmission>
  <!--
        <xacro:kinova_armlink link_name="${prefix}_link_7" link_mesh="${link_7_mesh}" use_ring_mesh="true" ring_mesh="ring_small" mesh_no="${link_7_mesh_no}"/>
        <xacro:kinova_armjoint joint_name="${prefix}_joint_7" type="${joint_7_type}" parent="${prefix}_link_6" child="${prefix}_link_7" joint_axis_xyz="${joint_7_axis_xyz}" joint_origin_xyz="${joint_7_origin_xyz}" joint_origin_rpy="${joint_7_origin_rpy}" joint_lower_limit="${joint_7_lower_limit}" joint_upper_limit="${joint_7_upper_limit}"/>    

        <xacro:kinova_virtual_link link_name="${prefix}_end_effector"/>
        <xacro:kinova_virtual_joint joint_name="${prefix}_joint_end_effector" type="${joint_end_effector_type}" parent="${prefix}_link_7" child="${prefix}_end_effector" joint_axis_xyz="${joint_end_effector_axis_xyz}" joint_origin_xyz="${joint_end_effector_origin_xyz}" joint_origin_rpy="${joint_end_effector_origin_rpy}" joint_lower_limit="0" joint_upper_limit="0"/>    

        <xacro:kinova_3fingers link_hand="${prefix}_link_7" prefix="${prefix}_"/>
        -->
  <!-- RAIL end-effector additions/modifications -->
  <joint name="j2s7s300_joint_7" type="continuous">
    <parent link="j2s7s300_link_6"/>
    <child link="j2s7s300_link_7"/>
    <origin rpy="1.57079632679 0 0" xyz="0 0.06075 0"/>
    <axis xyz="0 0 1"/>
    <limit effort="600.8" velocity="0.785"/>
    <dynamics damping="0.0" friction="0.0"/>
  </joint>
  <link name="j2s7s300_link_7">
    <visual>
      <geometry>
        <mesh filename="package://kinova_description/meshes/wrist_3.dae"/>
      </geometry>
    </visual>
    <collision>
      <geometry>
        <mesh filename="package://kinova_description/meshes/wrist_3.stl"/>
      </geometry>
    </collision>
  </link>
  <joint name="j2s7s300_ee_fixed_joint" type="fixed">
    <parent link="j2s7s300_link_7"/>
    <child link="j2s7s300_ee_base"/>
    <origin rpy="0 1.57079632679 0" xyz="0 0 -0.09380704"/>
  </joint>
  <link name="j2s7s300_ee_base"/>
  <joint name="j2s7s300_ee_gripper" type="fixed">
    <parent link="j2s7s300_ee_base"/>
    <child link="j2s7s300_ee_link"/>
    <origin xyz="0.13 0 0"/>
  </joint>
  <link name="j2s7s300_ee_link"/>
  <transmission name="j2s7s300_joint_7_trans">
    <type>transmission_interface/SimpleTransmission</type>
    <joint name="j2s7s300_joint_7">
      <hardwareInterface>PositionJointInterface</hardwareInterface>
    </joint>
    <actuator name="j2s7s300_joint_7_motor">
      <mechanicalReduction>1</mechanicalReduction>
    </actuator>
  </transmission>
  <joint name="j2s7s300_robotiq_85_base_joint" type="fixed">
    <parent link="j2s7s300_ee_base"/>
    <child link="j2s7s300_robotiq_85_base_link"/>
    <origin rpy="0 0 0" xyz="0 0 0"/>
  </joint>
  <link name="j2s7s300_robotiq_85_base_link">
    <visual>
      <geometry>
        <mesh filename="package://robotiq_85_description/meshes/visual/robotiq_85_base_link.dae"/>
      </geometry>
    </visual>
    <collision>
      <geometry>
        <mesh filename="package://robotiq_85_description/meshes/collision/robotiq_85_base_link.stl"/>
      </geometry>
    </collision>
    <inertial>
      <mass value="0.636951"/>
      <origin xyz="0.0 0.0 0.0"/>
      <inertia ixx="0.000380" ixy="0.000000" ixz="0.000000" iyx="0.000000" iyy="0.001110" iyz="0.000000" izx="0.000000" izy="0.000000" izz="0.001171"/>
    </inertial>
  </link>
  <joint name="j2s7s300_robotiq_85_left_knuckle_joint" type="revolute">
    <parent link="j2s7s300_robotiq_85_base_link"/>
    <child link="j2s7s300_robotiq_85_left_knuckle_link"/>
    <axis xyz="0 0 1"/>
    <origin rpy="3.14159265359 0.0 0.0" xyz="0.05490451627 0.03060114443 0.0"/>
    <limit effort="1000" lower="0.0" upper="0.804" velocity="2.0"/>
  </joint>
  <joint name="j2s7s300_robotiq_85_right_knuckle_joint" type="continuous">
    <parent link="j2s7s300_robotiq_85_base_link"/>
    <child link="j2s7s300_robotiq_85_right_knuckle_link"/>
    <axis xyz="0 0 1"/>
    <origin rpy="0.0 0.0 0.0" xyz="0.05490451627 -0.03060114443 0.0"/>
    <limit effort="1000" lower="-3.14" upper="3.14" velocity="100.0"/>
    <mimic joint="j2s7s300_robotiq_85_left_knuckle_joint"/>
  </joint>
  <link name="j2s7s300_robotiq_85_left_knuckle_link">
    <visual>
      <geometry>
        <mesh filename="package://robotiq_85_description/meshes/visual/robotiq_85_knuckle_link.dae"/>
      </geometry>
    </visual>
    <collision>
      <geometry>
        <mesh filename="package://robotiq_85_description/meshes/collision/robotiq_85_knuckle_link.stl"/>
      </geometry>
    </collision>
    <inertial>
      <mass value="0.018491"/>
      <origin xyz="0.0 0.0 0.0"/>
      <inertia ixx="0.000009" ixy="-0.000001" ixz="0.000000" iyx="-0.000001" iyy="0.000001" iyz="0.000000" izx="0.000000" izy="0.000000" izz="0.000010"/>
    </inertial>
  </link>
  <link name="j2s7s300_robotiq_85_right_knuckle_link">
    <visual>
      <geometry>
        <mesh filename="package://robotiq_85_description/meshes/visual/robotiq_85_knuckle_link.dae"/>
      </geometry>
    </visual>
    <collision>
      <geometry>
        <mesh filename="package://robotiq_85_description/meshes/collision/robotiq_85_knuckle_link.stl"/>
      </geometry>
    </collision>
    <inertial>
      <mass value="0.018491"/>
      <origin xyz="0.0 0.0 0.0"/>
      <inertia ixx="0.000009" ixy="-0.000001" ixz="0.000000" iyx="-0.000001" iyy="0.000001" iyz="0.000000" izx="0.000000" izy="0.000000" izz="0.000010"/>
    </inertial>
  </link>
  <joint name="j2s7s300_robotiq_85_left_finger_joint" type="fixed">
    <parent link="j2s7s300_robotiq_85_left_knuckle_link"/>
    <child link="j2s7s300_robotiq_85_left_finger_link"/>
    <origin rpy="0 0 0" xyz="-0.00408552455 -0.03148604435 0.0"/>
  </joint>
  <joint name="j2s7s300_robotiq_85_right_finger_joint" type="fixed">
    <parent link="j2s7s300_robotiq_85_right_knuckle_link"/>
    <child link="j2s7s300_robotiq_85_right_finger_link"/>
    <origin rpy="0 0 0" xyz="-0.00408552455 -0.03148604435 0.0"/>
  </joint>
  <link name="j2s7s300_robotiq_85_left_finger_link">
    <visual>
      <geometry>
        <mesh filename="package://robotiq_85_description/meshes/visual/robotiq_85_finger_link.dae"/>
      </geometry>
    </visual>
    <collision>
      <geometry>
        <mesh filename="package://robotiq_85_description/meshes/collision/robotiq_85_finger_link.stl"/>
      </geometry>
    </collision>
    <inertial>
      <mass value="0.027309"/>
      <origin xyz="0.0 0.0 0.0"/>
      <inertia ixx="0.000003" ixy="-0.000002" ixz="0.000000" iyx="-0.000002" iyy="0.000021" iyz="0.000000" izx="0.000000" izy="0.000000" izz="0.000020"/>
    </inertial>
  </link>
  <link name="j2s7s300_robotiq_85_right_finger_link">
    <visual>
      <geometry>
        <mesh filename="package://robotiq_85_description/meshes/visual/robotiq_85_finger_link.dae"/>
      </geometry>
    </visual>
    <collision>
      <geometry>
        <mesh filename="package://robotiq_85_description/meshes/collision/robotiq_85_finger_link.stl"/>
      </geometry>
    </collision>
    <inertial>
      <mass value="0.027309"/>
      <origin xyz="0.0 0.0 0.0"/>
      <inertia ixx="0.000003" ixy="-0.000002" ixz="0.000000" iyx="-0.000002" iyy="0.000021" iyz="0.000000" izx="0.000000" izy="0.000000" izz="0.000020"/>
    </inertial>
  </link>
  <joint name="j2s7s300_robotiq_85_left_inner_knuckle_joint" type="continuous">
    <parent link="j2s7s300_robotiq_85_base_link"/>
    <child link="j2s7s300_robotiq_85_left_inner_knuckle_link"/>
    <axis xyz="0 0 1"/>
    <origin rpy="3.14159265359 0.0 0.0" xyz="0.06142 0.0127 0"/>
    <limit effort="0.1" lower="-3.14" upper="3.14" velocity="100.0"/>
    <mimic joint="j2s7s300_robotiq_85_left_knuckle_joint" offset="0"/>
  </joint>
  <joint name="j2s7s300_robotiq_85_right_inner_knuckle_joint" type="continuous">
    <parent link="j2s7s300_robotiq_85_base_link"/>
    <child link="j2s7s300_robotiq_85_right_inner_knuckle_link"/>
    <axis xyz="0 0 1"/>
    <origin rpy="0 0 0" xyz="0.06142 -0.0127 0"/>
    <limit effort="0.1" lower="-3.14" upper="3.14" velocity="100.0"/>
    <mimic joint="j2s7s300_robotiq_85_left_knuckle_joint" offset="0"/>
  </joint>
  <link name="j2s7s300_robotiq_85_left_inner_knuckle_link">
    <visual>
      <geometry>
        <mesh filename="package://robotiq_85_description/meshes/visual/robotiq_85_inner_knuckle_link.dae"/>
      </geometry>
    </visual>
    <collision>
      <geometry>
        <mesh filename="package://robotiq_85_description/meshes/collision/robotiq_85_inner_knuckle_link.stl"/>
      </geometry>
    </collision>
    <inertial>
      <mass value="0.029951"/>
      <origin xyz="0.0 0.0 0.0"/>
      <inertia ixx="0.000039" ixy="0.000000" ixz="0.000000" iyx="0.000000" iyy="0.000005" iyz="0.000000" izx="0.000000" izy="0.000000" izz="0.000035"/>
    </inertial>
  </link>
  <link name="j2s7s300_robotiq_85_right_inner_knuckle_link">
    <visual>
      <geometry>
        <mesh filename="package://robotiq_85_description/meshes/visual/robotiq_85_inner_knuckle_link.dae"/>
      </geometry>
    </visual>
    <collision>
      <geometry>
        <mesh filename="package://robotiq_85_description/meshes/collision/robotiq_85_inner_knuckle_link.stl"/>
      </geometry>
    </collision>
    <inertial>
      <mass value="0.029951"/>
      <origin xyz="0.0 0.0 0.0"/>
      <inertia ixx="0.000039" ixy="0.000000" ixz="0.000000" iyx="0.000000" iyy="0.000005" iyz="0.000000" izx="0.000000" izy="0.000000" izz="0.000035"/>
    </inertial>
  </link>
  <joint name="j2s7s300_robotiq_85_left_finger_tip_joint" type="continuous">
    <parent link="j2s7s300_robotiq_85_left_inner_knuckle_link"/>
    <child link="j2s7s300_robotiq_85_left_finger_tip_link"/>
    <axis xyz="0 0 1"/>
    <origin rpy="0.0 0.0 0.0" xyz="0.04303959807 -0.03759940821 0.0"/>
    <limit effort="0.1" lower="-3.14" upper="3.14" velocity="100.0"/>
    <mimic joint="j2s7s300_robotiq_85_left_knuckle_joint" multiplier="-1"/>
  </joint>
  <joint name="j2s7s300_robotiq_85_right_finger_tip_joint" type="continuous">
    <parent link="j2s7s300_robotiq_85_right_inner_knuckle_link"/>
    <child link="j2s7s300_robotiq_85_right_finger_tip_link"/>
    <axis xyz="0 0 1"/>
    <origin rpy="0.0 0.0 0.0" xyz="0.04303959807 -0.03759940821  0.0"/>
    <limit effort="0.1" lower="-3.14" upper="3.14" velocity="100.0"/>
    <mimic joint="j2s7s300_robotiq_85_left_knuckle_joint" multiplier="-1"/>
  </joint>
  <link name="j2s7s300_robotiq_85_left_finger_tip_link">
    <visual>
      <geometry>
        <mesh filename="package://robotiq_85_description/meshes/visual/robotiq_85_finger_tip_link.dae"/>
      </geometry>
    </visual>
    <collision>
      <geometry>
        <mesh filename="package://robotiq_85_description/meshes/collision/robotiq_85_finger_tip_link.stl"/>
      </geometry>
    </collision>
    <inertial>
      <mass value="0.019555"/>
      <origin xyz="0.0 0.0 0.0"/>
      <inertia ixx="0.000002" ixy="0.000000" ixz="0.000000" iyx="0.000000" iyy="0.000005" iyz="0.000000" izx="0.000000" izy="0.000000" izz="0.000006"/>
    </inertial>
  </link>
  <link name="j2s7s300_robotiq_85_right_finger_tip_link">
    <visual>
      <geometry>
        <mesh filename="package://robotiq_85_description/meshes/visual/robotiq_85_finger_tip_link.dae"/>
      </geometry>
    </visual>
    <collision>
      <geometry>
        <mesh filename="package://robotiq_85_description/meshes/collision/robotiq_85_finger_tip_link.stl"/>
      </geometry>
    </collision>
    <inertial>
      <mass value="0.019555"/>
      <origin xyz="0.0 0.0 0.0"/>
      <inertia ixx="0.000002" ixy="0.000000" ixz="0.000000" iyx="0.000000" iyy="0.000005" iyz="0.000000" izx="0.000000" izy="0.000000" izz="0.000006"/>
    </inertial>
  </link>
  <transmission name="j2s7s300_robotiq_85_left_knuckle_trans">
    <type>transmission_interface/SimpleTransmission</type>
    <joint name="j2s7s300_robotiq_85_left_knuckle_joint">
      <hardwareInterface>PositionJointInterface</hardwareInterface>
    </joint>
    <actuator name="j2s7s300_robotiq_85_left_knuckle_motor">
      <mechanicalReduction>1</mechanicalReduction>
      <hardwareInterface>PositionJointInterface</hardwareInterface>
    </actuator>
  </transmission>
  <gazebo>
    <!-- loading plugin: mimic joints works in gazebo now -->
    <plugin filename="libroboticsgroup_gazebo_mimic_joint_plugin.so" name="j2s7s300_mimic_robotiq_85_1">
      <joint>j2s7s300_robotiq_85_left_knuckle_joint</joint>
      <mimicJoint>j2s7s300_robotiq_85_right_knuckle_joint</mimicJoint>
      <!--multiplier>1.0</multiplier>
                <offset>0.0</offset-->
    </plugin>
    <plugin filename="libroboticsgroup_gazebo_mimic_joint_plugin.so" name="j2s7s300_mimic_robotiq_85_2">
      <joint>j2s7s300_robotiq_85_left_knuckle_joint</joint>
      <mimicJoint>j2s7s300_robotiq_85_left_inner_knuckle_joint</mimicJoint>
      <!--multiplier>1.0</multiplier>
                <offset>0.0</offset-->
    </plugin>
    <plugin filename="libroboticsgroup_gazebo_mimic_joint_plugin.so" name="j2s7s300_mimic_robotiq_85_3">
      <joint>j2s7s300_robotiq_85_left_knuckle_joint</joint>
      <mimicJoint>j2s7s300_robotiq_85_right_inner_knuckle_joint</mimicJoint>
      <!--multiplier>1.0</multiplier>
                <offset>0.0</offset-->
    </plugin>
    <plugin filename="libroboticsgroup_gazebo_mimic_joint_plugin.so" name="j2s7s300_mimic_robotiq_85_4">
      <joint>j2s7s300_robotiq_85_left_knuckle_joint</joint>
      <mimicJoint>j2s7s300_robotiq_85_left_finger_tip_joint</mimicJoint>
      <multiplier>-1.0</multiplier>
      <offset>0.0</offset>
    </plugin>
    <plugin filename="libroboticsgroup_gazebo_mimic_joint_plugin.so" name="j2s7s300_mimic_robotiq_85_5">
      <joint>j2s7s300_robotiq_85_left_knuckle_joint</joint>
      <mimicJoint>j2s7s300_robotiq_85_right_finger_tip_joint</mimicJoint>
      <multiplier>-1.0</multiplier>
      <offset>0.0</offset>
    </plugin>
  </gazebo>
  <joint name="jaco_ee_link_nimbus_ee_link_joint" type="fixed">
    <parent link="j2s7s300_ee_link"/>
    <child link="nimbus_ee_link"/>
    <origin rpy="0 -1.57079632679 0" xyz="0 0 0"/>
  </joint>
  <link name="nimbus_ee_link"/>
  <!-- satellite camera -->
  <joint name="table_base_link_camera_side_link" type="fixed">
    <parent link="table_base_link"/>
    <child link="camera_side_link"/>
    <origin rpy="-0.019 0.077 1.523" xyz="-0.152 -1.175 0.328"/>
    <!-- Calibrated xyz and rpy for side camera go here (rosrun tf tf_echo /table_base_link /camera_side_link)-->
  </joint>
  <link name="camera_side_link"/>
  <joint name="table_base_link_sensor_frame_center_link_joint" type="fixed">
    <parent link="table_base_link"/>
    <child link="sensor_frame_center_link"/>
    <origin rpy="0 0 0" xyz="0 0.0508 0"/>
  </joint>
  <link name="sensor_frame_center_link"/>
  <joint name="sensor_frame_center_link_sensor_frame_left_strut_link_joint" type="fixed">
    <parent link="sensor_frame_center_link"/>
    <child link="sensor_frame_left_strut_link"/>
    <origin rpy="0 0 0" xyz="-0.8397875 0 0"/>
  </joint>
  <link name="sensor_frame_left_strut_link">
    <visual>
      <geometry>
        <box size="0.0254 0.0508 1.2192"/>
      </geometry>
      <origin rpy="0 0 0" xyz="0 0 0.6096"/>
      <material name="light-gray">
        <color rgba="0.4 0.4 0.4 1"/>
      </material>
    </visual>
    <collision>
      <geometry>
        <box size="0.0508 0.0762 1.2192"/>
      </geometry>
      <origin rpy="0 0 0" xyz="0 0 0.6096"/>
    </collision>
  </link>
  <joint name="sensor_frame_left_strut_link_sensor_frame_left_bracket_left_foot_link_joint" type="fixed">
    <parent link="sensor_frame_left_strut_link"/>
    <child link="sensor_frame_left_bracket_left_foot_link"/>
    <origin rpy="0 0 0" xyz="-0.0381 0 0"/>
  </joint>
  <link name="sensor_frame_left_bracket_left_foot_link">
    <visual>
      <geometry>
        <box size="0.0508 0.0508 0.015875"/>
      </geometry>
      <origin rpy="0 0 0" xyz="0 0 0.0079375"/>
      <material name="light-gray"/>
    </visual>
    <collision>
      <geometry>
        <box size="0.0708 0.0708 0.06"/>
      </geometry>
      <origin rpy="0 0 0" xyz="0 0 0.03"/>
    </collision>
  </link>
  <joint name="sensor_frame_left_bracket_left_foot_link_sensor_frame_left_bracket_left_side_link_joint" type="fixed">
    <parent link="sensor_frame_left_bracket_left_foot_link"/>
    <child link="sensor_frame_left_bracket_left_side_link"/>
    <origin rpy="0 0 0" xyz="0.01905 0 0"/>
  </joint>
  <link name="sensor_frame_left_bracket_left_side_link">
    <visual>
      <geometry>
        <box size="0.0127 0.0508 0.127"/>
      </geometry>
      <origin rpy="0 0 0" xyz="0 0 0.0635"/>
      <material name="light-gray"/>
    </visual>
    <collision>
      <geometry>
        <box size="0.0127 0.0508 0.127"/>
      </geometry>
      <origin rpy="0 0 0" xyz="0 0 0.0635"/>
    </collision>
  </link>
  <joint name="sensor_frame_left_strut_link_sensor_frame_left_bracket_right_foot_link_joint" type="fixed">
    <parent link="sensor_frame_left_strut_link"/>
    <child link="sensor_frame_left_bracket_right_foot_link"/>
    <origin rpy="0 0 0" xyz="0.0381 0 0"/>
  </joint>
  <link name="sensor_frame_left_bracket_right_foot_link">
    <visual>
      <geometry>
        <box size="0.0508 0.0508 0.015875"/>
      </geometry>
      <origin rpy="0 0 0" xyz="0 0 0.0079375"/>
      <material name="light-gray"/>
    </visual>
    <collision>
      <geometry>
        <box size="0.0708 0.0708 0.06"/>
      </geometry>
      <origin rpy="0 0 0" xyz="0 0 0.03"/>
    </collision>
  </link>
  <joint name="sensor_frame_left_bracket_right_foot_link_sensor_frame_left_bracket_right_side_link_joint" type="fixed">
    <parent link="sensor_frame_left_bracket_right_foot_link"/>
    <child link="sensor_frame_left_bracket_right_side_link"/>
    <origin rpy="0 0 0" xyz="-0.01905 0 0"/>
  </joint>
  <link name="sensor_frame_left_bracket_right_side_link">
    <visual>
      <geometry>
        <box size="0.0127 0.0508 0.127"/>
      </geometry>
      <origin rpy="0 0 0" xyz="0 0 0.0635"/>
      <material name="light-gray"/>
    </visual>
    <collision>
      <geometry>
        <box size="0.0127 0.0508 0.127"/>
      </geometry>
      <origin rpy="0 0 0" xyz="0 0 0.0635"/>
    </collision>
  </link>
  <joint name="sensor_frame_center_link_sensor_frame_right_strut_link_joint" type="fixed">
    <parent link="sensor_frame_center_link"/>
    <child link="sensor_frame_right_strut_link"/>
    <origin rpy="0 0 0" xyz="0.8397875 0 0"/>
  </joint>
  <link name="sensor_frame_right_strut_link">
    <visual>
      <geometry>
        <box size="0.0254 0.0508 1.2192"/>
      </geometry>
      <origin rpy="0 0 0" xyz="0 0 0.6096"/>
      <material name="light-gray"/>
    </visual>
    <collision>
      <geometry>
        <box size="0.0508 0.0762 1.2192"/>
      </geometry>
      <origin rpy="0 0 0" xyz="0 0 0.6096"/>
    </collision>
  </link>
  <joint name="sensor_frame_right_strut_link_sensor_frame_right_bracket_left_foot_link_joint" type="fixed">
    <parent link="sensor_frame_right_strut_link"/>
    <child link="sensor_frame_right_bracket_left_foot_link"/>
    <origin rpy="0 0 0" xyz="-0.0381 0 0"/>
  </joint>
  <link name="sensor_frame_right_bracket_left_foot_link">
    <visual>
      <geometry>
        <box size="0.0508 0.0508 0.015875"/>
      </geometry>
      <origin rpy="0 0 0" xyz="0 0 0.0079375"/>
      <material name="light-gray"/>
    </visual>
    <collision>
      <geometry>
        <box size="0.0708 0.0708 0.06"/>
      </geometry>
      <origin rpy="0 0 0" xyz="0 0 0.03"/>
    </collision>
  </link>
  <joint name="sensor_frame_right_bracket_left_foot_link_sensor_frame_right_bracket_left_side_link_joint" type="fixed">
    <parent link="sensor_frame_right_bracket_left_foot_link"/>
    <child link="sensor_frame_right_bracket_left_side_link"/>
    <origin rpy="0 0 0" xyz="0.01905 0 0"/>
  </joint>
  <link name="sensor_frame_right_bracket_left_side_link">
    <visual>
      <geometry>
        <box size="0.0127 0.0508 0.127"/>
      </geometry>
      <origin rpy="0 0 0" xyz="0 0 0.0635"/>
      <material name="light-gray"/>
    </visual>
    <collision>
      <geometry>
        <box size="0.0127 0.0508 0.127"/>
      </geometry>
      <origin rpy="0 0 0" xyz="0 0 0.0635"/>
    </collision>
  </link>
  <joint name="sensor_frame_right_strut_link_sensor_frame_right_bracket_right_foot_link_joint" type="fixed">
    <parent link="sensor_frame_right_strut_link"/>
    <child link="sensor_frame_right_bracket_right_foot_link"/>
    <origin rpy="0 0 0" xyz="0.0381 0 0"/>
  </joint>
  <link name="sensor_frame_right_bracket_right_foot_link">
    <visual>
      <geometry>
        <box size="0.0508 0.0508 0.015875"/>
      </geometry>
      <origin rpy="0 0 0" xyz="0 0 0.0079375"/>
      <material name="light-gray"/>
    </visual>
    <collision>
      <geometry>
        <box size="0.0708 0.0708 0.06"/>
      </geometry>
      <origin rpy="0 0 0" xyz="0 0 0.03"/>
    </collision>
  </link>
  <joint name="sensor_frame_right_bracket_right_foot_link_sensor_frame_right_bracket_right_side_link_joint" type="fixed">
    <parent link="sensor_frame_right_bracket_right_foot_link"/>
    <child link="sensor_frame_right_bracket_right_side_link"/>
    <origin rpy="0 0 0" xyz="-0.01905 0 0"/>
  </joint>
  <link name="sensor_frame_right_bracket_right_side_link">
    <visual>
      <geometry>
        <box size="0.0127 0.0508 0.127"/>
      </geometry>
      <origin rpy="0 0 0" xyz="0 0 0.0635"/>
      <material name="light-gray"/>
    </visual>
    <collision>
      <geometry>
        <box size="0.0127 0.0508 0.127"/>
      </geometry>
      <origin rpy="0 0 0" xyz="0 0 0.0635"/>
    </collision>
  </link>
  <joint name="sensor_frame_center_link_sensor_frame_top_beam_link_joint" type="fixed">
    <parent link="sensor_frame_center_link"/>
    <child link="sensor_frame_top_beam_link"/>
    <origin rpy="0 0 0" xyz="0 0 1.2319"/>
  </joint>
  <link name="sensor_frame_top_beam_link">
    <visual>
      <geometry>
        <box size="1.8288 0.0508 0.0254"/>
      </geometry>
      <material name="light-gray"/>
    </visual>
    <collision>
      <geometry>
        <box size="1.8888 0.1108 0.0854"/>
      </geometry>
    </collision>
  </link>
  <joint name="sensor_frame_top_beam_link_sensor_frame_sensor_link_joint" type="fixed">
    <parent link="sensor_frame_top_beam_link"/>
    <child link="sensor_frame_sensor_link"/>
    <origin rpy="0 1.57079632679 1.57079632679" xyz="0.0 0.07 -0.038"/>
  </joint>
  <link name="sensor_frame_sensor_link"/>
  <joint name="camera_rgb_joint" type="fixed">
    <origin rpy="0.006 -0.224 -0.009" xyz="-0.003 -0.025 -0.003"/>
    <parent link="sensor_frame_sensor_link"/>
    <child link="camera_rgb_frame"/>
  </joint>
  <link name="camera_rgb_frame"/>
  <joint name="camera_rgb_optical_joint" type="fixed">
    <origin rpy="-1.57079632679 0 -1.57079632679" xyz="0 0 0"/>
    <parent link="camera_rgb_frame"/>
    <child link="camera_rgb_optical_frame"/>
  </joint>
  <link name="camera_rgb_optical_frame"/>
  <joint name="camera_joint" type="fixed">
    <origin rpy="0 0 0" xyz="0 -0.022 0"/>
    <parent link="camera_rgb_frame"/>
    <child link="camera_link"/>
  </joint>
  <link name="camera_link">
    <visual>
      <origin rpy="0 0 0" xyz="-0.015 0.0035 0.004"/>
      <geometry>
        <mesh filename="package://nimbus_description/meshes/xtion_pro_camera.dae"/>
      </geometry>
    </visual>
    <collision>
      <origin rpy="0 0 0" xyz="0.0 0.0 0.0"/>
      <geometry>
        <box size="0.0730 0.2760 0.0720"/>
      </geometry>
    </collision>
    <inertial>
      <mass value="0.170"/>
      <origin xyz="0 0 0"/>
      <inertia ixx="0.001152600" ixy="0.0" ixz="0.0" iyy="0.000148934" iyz="0.0" izz="0.001154654"/>
    </inertial>
  </link>
  <joint name="camera_depth_joint" type="fixed">
    <origin rpy="0 0 0" xyz="0 0.027 0"/>
    <parent link="camera_rgb_frame"/>
    <child link="camera_depth_frame"/>
  </joint>
  <link name="camera_depth_frame"/>
  <joint name="camera_depth_optical_joint" type="fixed">
    <origin rpy="-1.57079632679 0 -1.57079632679" xyz="0 0 0"/>
    <parent link="camera_depth_frame"/>
    <child link="camera_depth_optical_frame"/>
  </joint>
  <link name="camera_depth_optical_frame"/>
  <!-- RGBD sensor for simulation, same as Kinect -->
  <gazebo reference="camera_link">
    <sensor name="camera" type="depth">
      <always_on>true</always_on>
      <update_rate>20.0</update_rate>
      <camera>
        <horizontal_fov>1.0471975512</horizontal_fov>
        <image>
          <format>R8G8B8</format>
          <width>640</width>
          <height>480</height>
        </image>
        <clip>
          <near>0.05</near>
          <far>8.0</far>
        </clip>
      </camera>
      <plugin filename="libgazebo_ros_openni_kinect.so" name="kinect_camera_controller">
        <cameraName>camera</cameraName>
        <alwaysOn>true</alwaysOn>
        <updateRate>10</updateRate>
        <imageTopicName>rgb/image_raw</imageTopicName>
        <depthImageTopicName>depth/image_raw</depthImageTopicName>
        <pointCloudTopicName>depth/points</pointCloudTopicName>
        <cameraInfoTopicName>rgb/camera_info</cameraInfoTopicName>
        <depthImageCameraInfoTopicName>depth/camera_info</depthImageCameraInfoTopicName>
        <frameName>camera_depth_optical_frame</frameName>
        <baseline>0.1</baseline>
        <distortion_k1>0.0</distortion_k1>
        <distortion_k2>0.0</distortion_k2>
        <distortion_k3>0.0</distortion_k3>
        <distortion_t1>0.0</distortion_t1>
        <distortion_t2>0.0</distortion_t2>
        <pointCloudCutoff>0.4</pointCloudCutoff>
      </plugin>
    </sensor>
  </gazebo>
</robot>

