<?xml version="1.0" ?>
<!-- =================================================================================== -->
<!-- |    This document was autogenerated by xacro from nimbus.urdf.xacro              | -->
<!-- |    EDITING THIS FILE BY HAND IS NOT RECOMMENDED                                 | -->
<!-- =================================================================================== -->
<robot name="nimbus" xmlns:controller="http://playerstage.sourceforge.net/gazebo/xmlschema/#controller" xmlns:interface="http://playerstage.sourceforge.net/gazebo/xmlschema/#interface" xmlns:sensor="http://playerstage.sourceforge.net/gazebo/xmlschema/#sensor" xmlns:xacro="http://ros.org/wiki/xacro">
  <!--
  Author: Kelsey Hawkins 
  Contributers: Jimmy Da Silva, Ajit Krisshna N L, Muhammad Asif Rana 
-->
  <!-- Inertia parameters -->
  <!--
  Author: David Kent
  Very simplified arm model for use in self-subtraction of point clouds (significantly improves runtime)
-->
  <!-- Xacro properties -->
  <!-- Xacro properties -->
  <!-- Xacro properties -->
  <!-- Xacro properties -->
  <link name="table_base_link">
    <!--
    <visual>
      <geometry>
        <cylinder length="0.022" radius=".9144"/>
      </geometry>
      <origin rpy="0 0 0" xyz="0 0 -0.011" />
      <material name="tan">
        <color rgba="0.871 0.722 0.529 1" />
      </material>
    </visual>
    <collision>
      <geometry>
        <cylinder length="0.022" radius=".9144"/>
      </geometry>
      <origin rpy="0 0 0" xyz="0 0 -0.011" />
    </collision>
    -->
  </link>
  <xacro:nimbus_kinect parent="table_base_link">
    <origin rpy="0 0 0" xyz="0 0 0"/>
  </xacro:nimbus_kinect>
  <joint name="table_base_link_arm_mount_plate_link_joint" type="fixed">
    <parent link="table_base_link"/>
    <child link="arm_mount_plate_link"/>
    <origin rpy="0 0 0" xyz="0 0.0762 0"/>
  </joint>
  <link name="arm_mount_plate_link">
    <visual>
      <geometry>
        <box size="0.2032 0.1524 0.015875"/>
      </geometry>
      <origin rpy="0 0 0" xyz="0 0 0.0079375"/>
      <material name="dark-gray">
        <color rgba="0.2 0.2 0.2 1"/>
      </material>
    </visual>
    <collision>
      <geometry>
        <box size="0.2032 0.1524 0.015875"/>
      </geometry>
      <origin rpy="0 0 0" xyz="0 0 0.0079375"/>
    </collision>
  </link>
  <joint name="arm_mount_plate_link_arm_mount_beam_link_joint" type="fixed">
    <parent link="arm_mount_plate_link"/>
    <child link="arm_mount_beam_link"/>
    <origin rpy="0 0 0" xyz="0 0 0"/>
  </joint>
  <link name="arm_mount_beam_link">
    <visual>
      <geometry>
        <box size="0.0396875 0.0396875 0.0889"/>
      </geometry>
      <origin rpy="0 0 0" xyz="0 0 0.04445"/>
      <material name="dark-gray"/>
    </visual>
    <collision>
      <geometry>
        <box size="0.0396875 0.0396875 0.0889"/>
      </geometry>
      <origin rpy="0 0 0" xyz="0 0 0.04445"/>
    </collision>
  </link>
  <joint name="jaco_base_joint" type="fixed">
    <parent link="arm_mount_beam_link"/>
    <child link="jaco_base_link"/>
    <origin rpy="0 0 3.14159265359" xyz="0 0 0.0508"/>
  </joint>
  <link name="jaco_base_link">
    <visual>
      <geometry>
        <mesh filename="package://jaco2_description/meshes/jaco/visual/base.dae"/>
      </geometry>
    </visual>
    <collision>
      <geometry>
        <mesh filename="package://jaco2_description/meshes/jaco/collision/base.stl"/>
      </geometry>
    </collision>
    <inertial>
      <mass value="0.752103"/>
      <origin xyz="0 0 0"/>
      <inertia ixx="0.009025" ixy="-0.000002" ixz="-0.000005" iyx="-0.000002" iyy="0.009007" iyz="0.000000" izx="-0.000005" izy="0.000000" izz="0.000704"/>
    </inertial>
  </link>
  <joint name="jaco_shoulder_pan_joint" type="continuous">
    <parent link="jaco_base_link"/>
    <child link="jaco_shoulder_link"/>
    <origin rpy="0 0 -1.57079632679" xyz="0.0 0.0 0.15675"/>
    <axis xyz="0 0 -1"/>
    <limit effort="18.0" velocity="0.75"/>
    <dynamics damping="0.0" friction="0.0"/>
  </joint>
  <link name="jaco_shoulder_link">
    <visual>
      <geometry>
        <mesh filename="package://jaco2_description/meshes/jaco/visual/shoulder.dae"/>
      </geometry>
    </visual>
    <collision>
      <geometry>
        <mesh filename="package://jaco2_description/meshes/jaco/collision/shoulder.stl"/>
      </geometry>
    </collision>
    <inertial>
      <mass value="0.839784"/>
      <origin xyz="0 0 0"/>
      <inertia ixx="0.005735" ixy="0.000000" ixz="0.000000" iyx="0.000000" iyy="0.005801" iyz="0.000496" izx="0.000000" izy="0.000496" izz="0.000570"/>
    </inertial>
  </link>
  <joint name="jaco_shoulder_lift_joint" type="revolute">
    <parent link="jaco_shoulder_link"/>
    <child link="jaco_upper_arm_link"/>
    <origin rpy="0 1.57079632679 0" xyz="0.0 0.0 0.11875"/>
    <axis xyz="0 0 1"/>
    <limit effort="30.5" lower="0.872665" upper="5.41052" velocity="1.0"/>
    <dynamics damping="0.0" friction="0.0"/>
  </joint>
  <link name="jaco_upper_arm_link">
    <visual>
      <geometry>
        <mesh filename="package://jaco2_description/meshes/jaco/visual/upper_arm.dae"/>
      </geometry>
    </visual>
    <collision>
      <geometry>
        <mesh filename="package://jaco2_description/meshes/jaco/collision/upper_arm.stl"/>
      </geometry>
    </collision>
    <inertial>
      <mass value="0.968862"/>
      <origin xyz="0 0 0"/>
      <inertia ixx="0.000789" ixy="0.000008" ixz="-0.002914" iyx="0.000008" iyy="0.069034" iyz="-0.000001" izx="-0.002914" izy="-0.000001" izz="0.069005"/>
    </inertial>
  </link>
  <joint name="jaco_elbow_joint" type="revolute">
    <parent link="jaco_upper_arm_link"/>
    <child link="jaco_forearm_link"/>
    <origin rpy="0.0 0.0 3.14159265359" xyz="0.410 0.0 0.00975"/>
    <axis xyz="0 0 -1"/>
    <limit effort="18.0" lower="0.331613" upper="5.95157" velocity="0.75"/>
    <dynamics damping="0.0" friction="0.0"/>
  </joint>
  <link name="jaco_forearm_link">
    <visual>
      <geometry>
        <mesh filename="package://jaco2_description/meshes/jaco/visual/forearm.dae"/>
      </geometry>
    </visual>
    <collision>
      <geometry>
        <mesh filename="package://jaco2_description/meshes/jaco/collision/forearm.stl"/>
      </geometry>
    </collision>
    <inertial>
      <mass value="0.70996"/>
      <origin xyz="0 0 0"/>
      <inertia ixx="0.000341" ixy="0.000003" ixz="-0.000034" iyx="0.000003" iyy="0.008491" iyz="-0.000000" izx="-0.000034" izy="0.000000" izz="0.008612"/>
    </inertial>
  </link>
  <joint name="jaco_wrist_1_joint" type="continuous">
    <parent link="jaco_forearm_link"/>
    <child link="jaco_wrist_1_link"/>
    <origin rpy="3.14159265359 1.57079632679 3.14159265359" xyz="0.20725 0.0 0.0"/>
    <axis xyz="0 0 -1"/>
    <limit effort="6.8" velocity="1.571"/>
    <dynamics damping="0.0" friction="0.0"/>
  </joint>
  <link name="jaco_wrist_1_link">
    <visual>
      <geometry>
        <mesh filename="package://jaco2_description/meshes/jaco/visual/wrist_1.dae"/>
      </geometry>
    </visual>
    <collision>
      <geometry>
        <mesh filename="package://jaco2_description/meshes/jaco/collision/wrist_1.stl"/>
      </geometry>
    </collision>
    <inertial>
      <mass value="0.441232"/>
      <origin xyz="0 0 0"/>
      <inertia ixx="0.000924" ixy="0.000000" ixz="-0.000294" iyx="0.000000" iyy="0.001034" iyz="0.000000" izx="-0.000294" izy="0.000000" izz="0.000312"/>
    </inertial>
  </link>
  <joint name="jaco_wrist_2_joint" type="continuous">
    <parent link="jaco_wrist_1_link"/>
    <child link="jaco_wrist_2_link"/>
    <origin rpy="0.0 1.0471975512 0.0" xyz="0.0 0.0 0.04275704155"/>
    <axis xyz="0 0 -1"/>
    <limit effort="6.8" velocity="1.571"/>
    <dynamics damping="0.0" friction="0.0"/>
  </joint>
  <link name="jaco_wrist_2_link">
    <visual>
      <geometry>
        <mesh filename="package://jaco2_description/meshes/jaco/visual/wrist_2.dae"/>
      </geometry>
    </visual>
    <collision>
      <geometry>
        <mesh filename="package://jaco2_description/meshes/jaco/collision/wrist_2.stl"/>
      </geometry>
    </collision>
    <inertial>
      <mass value="0.441232"/>
      <origin xyz="0 0 0"/>
      <inertia ixx="0.003063" ixy="0.000000" ixz="-0.000522" iyx="0.000000" iyy="0.003174" iyz="-0.000001" izx="-0.000522" izy="-0.000001" izz="0.000312"/>
    </inertial>
  </link>
  <joint name="jaco_wrist_3_joint" type="continuous">
    <parent link="jaco_wrist_2_link"/>
    <child link="jaco_wrist_3_link"/>
    <origin rpy="0.0 -1.0471975512 0.0" xyz="0.0 0.0 0.08551408311"/>
    <axis xyz="0 0 -1"/>
    <limit effort="6.8" velocity="1.571"/>
    <dynamics damping="0.0" friction="0.0"/>
  </joint>
  <link name="jaco_wrist_3_link">
    <visual>
      <geometry>
        <mesh filename="package://jaco2_description/meshes/jaco/visual/wrist_3.dae"/>
      </geometry>
    </visual>
    <collision>
      <geometry>
        <mesh filename="package://jaco2_description/meshes/jaco/collision/wrist_3.stl"/>
      </geometry>
    </collision>
    <inertial>
      <mass value="0.36329"/>
      <origin xyz="0 0 0"/>
      <inertia ixx="0.001908" ixy="0.000000" ixz="0.000000" iyx="0.000000" iyy="0.001907" iyz="0.000000" izx="0.000000" izy="0.000001" izz="0.000209"/>
    </inertial>
  </link>
  <joint name="jaco_ee_fixed_joint" type="fixed">
    <parent link="jaco_wrist_3_link"/>
    <child link="jaco_ee_link"/>
    <origin rpy="0.0 0.0 0.0 " xyz="0.0 0.0 0.14934664"/>
    <!--0.09380704156-->
  </joint>
  <link name="jaco_ee_link"/>
  <!--  /\  -->
  <joint name="robotiq_85_base_joint" type="fixed">
    <parent link="jaco_ee_link"/>
    <child link="robotiq_85_base_link"/>
    <axis xyz="0 0 1"/>
    <origin rpy="-1.57079632679 -1.57079632679 0" xyz="0.0 0.0 -0.055499598"/>
  </joint>
  <!--  \/  -->
  <link name="robotiq_85_base_link">
    <visual>
      <geometry>
        <mesh filename="package://kinova_description/meshes/robotiq_85_gripper/visual/robotiq_85_base_link.dae"/>
      </geometry>
    </visual>
    <collision>
      <geometry>
        <mesh filename="package://kinova_description/meshes/robotiq_85_gripper/collision/robotiq_85_base_link.stl"/>
      </geometry>
    </collision>
    <inertial>
      <mass value="0.636951"/>
      <origin xyz="0.0 0.0 0.0"/>
      <inertia ixx="0.000380" ixy="0.000000" ixz="0.000000" iyx="0.000000" iyy="0.001110" iyz="0.000000" izx="0.000000" izy="0.000000" izz="0.001171"/>
    </inertial>
  </link>
  <!--  /\  -->
  <!--  /\  -->
  <joint name="robotiq_85_left_knuckle_joint" type="revolute">
    <parent link="robotiq_85_base_link"/>
    <child link="robotiq_85_left_knuckle_link"/>
    <axis xyz="0 0 1"/>
    <origin rpy="3.14159265359 0.0 0.0" xyz="0.05490451627 0.03060114443 0.0"/>
    <limit effort="1000" lower="0.0" upper="0.804" velocity="2.0"/>
  </joint>
  <joint name="robotiq_85_right_knuckle_joint" type="revolute">
    <parent link="robotiq_85_base_link"/>
    <child link="robotiq_85_right_knuckle_link"/>
    <axis xyz="0 0 1"/>
    <origin rpy="0.0 0.0 0.0" xyz="0.05490451627 -0.03060114443 0.0"/>
    <limit effort="1000" lower="-0.804" upper="0.0" velocity="2.0"/>
    <mimic joint="robotiq_85_left_knuckle_joint" multiplier="1"/>
  </joint>
  <gazebo>
    <plugin filename="libroboticsgroup_gazebo_mimic_joint_plugin.so" name="robotiq_85_right_knuckle_joint_mimic">
      <joint>robotiq_85_left_knuckle_joint</joint>
      <mimicJoint>robotiq_85_right_knuckle_joint</mimicJoint>
    </plugin>
    <plugin filename="libroboticsgroup_gazebo_disable_link_plugin.so" name="robotiq_85_right_knuckle_link">
      <link>robotiq_85_right_knuckle_link</link>
    </plugin>
  </gazebo>
  <!--  \/  -->
  <!--  \/  -->
  <link name="robotiq_85_left_knuckle_link">
    <visual>
      <geometry>
        <mesh filename="package://kinova_description/meshes/robotiq_85_gripper/visual/robotiq_85_knuckle_link.dae"/>
      </geometry>
    </visual>
    <collision>
      <geometry>
        <mesh filename="package://kinova_description/meshes/robotiq_85_gripper/collision/robotiq_85_knuckle_link.stl"/>
      </geometry>
    </collision>
    <inertial>
      <mass value="0.018491"/>
      <origin xyz="0.0 0.0 0.0"/>
      <inertia ixx="0.000009" ixy="-0.000001" ixz="0.000000" iyx="-0.000001" iyy="0.000001" iyz="0.000000" izx="0.000000" izy="0.000000" izz="0.000010"/>
    </inertial>
  </link>
  <link name="robotiq_85_right_knuckle_link">
    <visual>
      <geometry>
        <mesh filename="package://kinova_description/meshes/robotiq_85_gripper/visual/robotiq_85_knuckle_link.dae"/>
      </geometry>
    </visual>
    <collision>
      <geometry>
        <mesh filename="package://kinova_description/meshes/robotiq_85_gripper/collision/robotiq_85_knuckle_link.stl"/>
      </geometry>
    </collision>
    <inertial>
      <mass value="0.018491"/>
      <origin xyz="0.0 0.0 0.0"/>
      <inertia ixx="0.000009" ixy="-0.000001" ixz="0.000000" iyx="-0.000001" iyy="0.000001" iyz="0.000000" izx="0.000000" izy="0.000000" izz="0.000010"/>
    </inertial>
  </link>
  <!--  /\  -->
  <!--  /\  -->
  <joint name="robotiq_85_left_finger_joint" type="fixed">
    <parent link="robotiq_85_left_knuckle_link"/>
    <child link="robotiq_85_left_finger_link"/>
    <axis xyz="0 0 1"/>
    <origin rpy="0 0 0" xyz="-0.00408552455 -0.03148604435 0.0"/>
    <limit effort="1000" lower="0" upper="2.617994" velocity="2.0"/>
  </joint>
  <joint name="robotiq_85_right_finger_joint" type="fixed">
    <parent link="robotiq_85_right_knuckle_link"/>
    <child link="robotiq_85_right_finger_link"/>
    <axis xyz="0 0 1"/>
    <origin rpy="0 0 0" xyz="-0.00408552455 -0.03148604435 0.0"/>
    <limit effort="0" lower="0" upper="2.617994" velocity="2.0"/>
  </joint>
  <!--  \/  -->
  <!--  \/  -->
  <link name="robotiq_85_left_finger_link">
    <visual>
      <geometry>
        <mesh filename="package://kinova_description/meshes/robotiq_85_gripper/visual/robotiq_85_finger_link.dae"/>
      </geometry>
    </visual>
    <collision>
      <geometry>
        <mesh filename="package://kinova_description/meshes/robotiq_85_gripper/collision/robotiq_85_finger_link.stl"/>
      </geometry>
    </collision>
    <inertial>
      <mass value="0.027309"/>
      <origin xyz="0.0 0.0 0.0"/>
      <inertia ixx="0.000003" ixy="-0.000002" ixz="0.000000" iyx="-0.000002" iyy="0.000021" iyz="0.000000" izx="0.000000" izy="0.000000" izz="0.000020"/>
    </inertial>
  </link>
  <link name="robotiq_85_right_finger_link">
    <visual>
      <geometry>
        <mesh filename="package://kinova_description/meshes/robotiq_85_gripper/visual/robotiq_85_finger_link.dae"/>
      </geometry>
    </visual>
    <collision>
      <geometry>
        <mesh filename="package://kinova_description/meshes/robotiq_85_gripper/collision/robotiq_85_finger_link.stl"/>
      </geometry>
    </collision>
    <inertial>
      <mass value="0.027309"/>
      <origin xyz="0.0 0.0 0.0"/>
      <inertia ixx="0.000003" ixy="-0.000002" ixz="0.000000" iyx="-0.000002" iyy="0.000021" iyz="0.000000" izx="0.000000" izy="0.000000" izz="0.000020"/>
    </inertial>
  </link>
  <!--  /\  -->
  <!--  /\  -->
  <joint name="robotiq_85_left_inner_knuckle_joint" type="revolute">
    <parent link="robotiq_85_base_link"/>
    <child link="robotiq_85_left_inner_knuckle_link"/>
    <axis xyz="0 0 1"/>
    <origin rpy="3.14159265359 0.0 0.0" xyz="0.06142 0.0127 0"/>
    <limit effort="1000" lower="-0.804" upper="0.0" velocity="2.0"/>
    <mimic joint="robotiq_85_left_knuckle_joint" offset="0"/>
  </joint>
  <gazebo>
    <plugin filename="libroboticsgroup_gazebo_mimic_joint_plugin.so" name="robotiq_85_left_inner_knuckle_joint_mimic">
      <joint>robotiq_85_left_knuckle_joint</joint>
      <mimicJoint>robotiq_85_left_inner_knuckle_joint</mimicJoint>
    </plugin>
    <plugin filename="libroboticsgroup_gazebo_disable_link_plugin.so" name="robotiq_85_left_inner_knuckle_link">
      <link>robotiq_85_left_inner_knuckle_link</link>
    </plugin>
  </gazebo>
  <joint name="robotiq_85_right_inner_knuckle_joint" type="revolute">
    <parent link="robotiq_85_base_link"/>
    <child link="robotiq_85_right_inner_knuckle_link"/>
    <axis xyz="0 0 1"/>
    <origin rpy="0 0 0" xyz="0.06142 -0.0127 0"/>
    <limit effort="1000" lower="0" upper="0.804" velocity="2.0"/>
    <mimic joint="robotiq_85_left_knuckle_joint" offset="0"/>
  </joint>
  <gazebo>
    <plugin filename="libroboticsgroup_gazebo_mimic_joint_plugin.so" name="robotiq_85_right_inner_knuckle_joint_mimic">
      <joint>robotiq_85_left_knuckle_joint</joint>
      <mimicJoint>robotiq_85_right_inner_knuckle_joint</mimicJoint>
    </plugin>
    <plugin filename="libroboticsgroup_gazebo_disable_link_plugin.so" name="robotiq_85_right_inner_knuckle_link">
      <link>robotiq_85_right_inner_knuckle_link</link>
    </plugin>
  </gazebo>
  <!--  \/  -->
  <!--  \/  -->
  <link name="robotiq_85_left_inner_knuckle_link">
    <visual>
      <geometry>
        <mesh filename="package://kinova_description/meshes/robotiq_85_gripper/visual/robotiq_85_inner_knuckle_link.dae"/>
      </geometry>
    </visual>
    <collision>
      <geometry>
        <mesh filename="package://kinova_description/meshes/robotiq_85_gripper/collision/robotiq_85_inner_knuckle_link.stl"/>
      </geometry>
    </collision>
    <inertial>
      <mass value="0.029951"/>
      <origin xyz="0.0 0.0 0.0"/>
      <inertia ixx="0.000039" ixy="0.000000" ixz="0.000000" iyx="0.000000" iyy="0.000005" iyz="0.000000" izx="0.000000" izy="0.000000" izz="0.000035"/>
    </inertial>
  </link>
  <link name="robotiq_85_right_inner_knuckle_link">
    <visual>
      <geometry>
        <mesh filename="package://kinova_description/meshes/robotiq_85_gripper/visual/robotiq_85_inner_knuckle_link.dae"/>
      </geometry>
    </visual>
    <collision>
      <geometry>
        <mesh filename="package://kinova_description/meshes/robotiq_85_gripper/collision/robotiq_85_inner_knuckle_link.stl"/>
      </geometry>
    </collision>
    <inertial>
      <mass value="0.029951"/>
      <origin xyz="0.0 0.0 0.0"/>
      <inertia ixx="0.000039" ixy="0.000000" ixz="0.000000" iyx="0.000000" iyy="0.000005" iyz="0.000000" izx="0.000000" izy="0.000000" izz="0.000035"/>
    </inertial>
  </link>
  <!--  /\  -->
  <!--  /\  -->
  <joint name="robotiq_85_left_finger_tip_joint" type="revolute">
    <parent link="robotiq_85_left_inner_knuckle_link"/>
    <child link="robotiq_85_left_finger_tip_link"/>
    <axis xyz="0 0 1"/>
    <origin rpy="0.0 0.0 0.0" xyz="0.04303959807 -0.03759940821 0.0"/>
    <limit effort="1000" lower="0" upper="1.5707" velocity="2.0"/>
    <mimic joint="robotiq_85_left_knuckle_joint" multiplier="-1"/>
  </joint>
  <gazebo>
    <plugin filename="libroboticsgroup_gazebo_mimic_joint_plugin.so" name="robotiq_85_left_finger_tip_joint_mimic">
      <joint>robotiq_85_left_knuckle_joint</joint>
      <mimicJoint>robotiq_85_left_finger_tip_joint</mimicJoint>
      <multiplier>-1</multiplier>
    </plugin>
    <plugin filename="libroboticsgroup_gazebo_disable_link_plugin.so" name="robotiq_85_left_finger_tip_link">
      <link>robotiq_85_left_finger_tip_link</link>
    </plugin>
  </gazebo>
  <joint name="robotiq_85_right_finger_tip_joint" type="revolute">
    <parent link="robotiq_85_right_inner_knuckle_link"/>
    <child link="robotiq_85_right_finger_tip_link"/>
    <axis xyz="0 0 1"/>
    <origin rpy="0.0 0.0 0.0" xyz="0.04303959807 -0.03759940821  0.0"/>
    <limit effort="1000" lower="0" upper="1.5707" velocity="2.0"/>
    <mimic joint="robotiq_85_left_knuckle_joint" multiplier="-1"/>
  </joint>
  <gazebo>
    <plugin filename="libroboticsgroup_gazebo_mimic_joint_plugin.so" name="robotiq_85_right_finger_tip_joint_mimic">
      <joint>robotiq_85_left_knuckle_joint</joint>
      <mimicJoint>robotiq_85_right_finger_tip_joint</mimicJoint>
      <multiplier>-1</multiplier>
    </plugin>
    <plugin filename="libroboticsgroup_gazebo_disable_link_plugin.so" name="robotiq_85_right_finger_tip_link">
      <link>robotiq_85_right_finger_tip_link</link>
    </plugin>
  </gazebo>
  <!--  \/  -->
  <!--  \/  -->
  <link name="robotiq_85_left_finger_tip_link">
    <visual>
      <geometry>
        <mesh filename="package://kinova_description/meshes/robotiq_85_gripper/visual/robotiq_85_finger_tip_link.dae"/>
      </geometry>
    </visual>
    <collision>
      <geometry>
        <mesh filename="package://kinova_description/meshes/robotiq_85_gripper/collision/robotiq_85_finger_tip_link.stl"/>
      </geometry>
    </collision>
    <inertial>
      <mass value="0.019555"/>
      <origin xyz="0.0 0.0 0.0"/>
      <inertia ixx="0.000002" ixy="0.000000" ixz="0.000000" iyx="0.000000" iyy="0.000005" iyz="0.000000" izx="0.000000" izy="0.000000" izz="0.000006"/>
    </inertial>
  </link>
  <link name="robotiq_85_right_finger_tip_link">
    <visual>
      <geometry>
        <mesh filename="package://kinova_description/meshes/robotiq_85_gripper/visual/robotiq_85_finger_tip_link.dae"/>
      </geometry>
    </visual>
    <collision>
      <geometry>
        <mesh filename="package://kinova_description/meshes/robotiq_85_gripper/collision/robotiq_85_finger_tip_link.stl"/>
      </geometry>
    </collision>
    <inertial>
      <mass value="0.019555"/>
      <origin xyz="0.0 0.0 0.0"/>
      <inertia ixx="0.000002" ixy="0.000000" ixz="0.000000" iyx="0.000000" iyy="0.000005" iyz="0.000000" izx="0.000000" izy="0.000000" izz="0.000006"/>
    </inertial>
  </link>
  <transmission name="robotiq_85_left_knuckle_trans">
    <type>transmission_interface/SimpleTransmission</type>
    <joint name="robotiq_85_left_knuckle_joint">
      <hardwareInterface>PositionJointInterface</hardwareInterface>
    </joint>
    <actuator name="robotiq_85_left_knuckle_motor">
      <mechanicalReduction>1</mechanicalReduction>
    </actuator>
  </transmission>
  <transmission name="robotiq_85_right_knuckle_trans">
    <type>transmission_interface/SimpleTransmission</type>
    <joint name="robotiq_85_right_knuckle_joint">
      <hardwareInterface>PositionJointInterface</hardwareInterface>
    </joint>
    <actuator name="robotiq_85_right_knuckle_motor">
      <mechanicalReduction>1</mechanicalReduction>
    </actuator>
  </transmission>
  <transmission name="robotiq_85_left_inner_knuckle_trans">
    <type>transmission_interface/SimpleTransmission</type>
    <joint name="robotiq_85_left_inner_knuckle_joint">
      <hardwareInterface>PositionJointInterface</hardwareInterface>
    </joint>
    <actuator name="robotiq_85_left_inner_knuckle_motor">
      <mechanicalReduction>1</mechanicalReduction>
    </actuator>
  </transmission>
  <transmission name="robotiq_85_right_inner_knuckle_trans">
    <type>transmission_interface/SimpleTransmission</type>
    <joint name="robotiq_85_right_inner_knuckle_joint">
      <hardwareInterface>PositionJointInterface</hardwareInterface>
    </joint>
    <actuator name="robotiq_85_right_inner_knuckle_motor">
      <mechanicalReduction>1</mechanicalReduction>
    </actuator>
  </transmission>
  <!--transmission name="${prefix}robotiq_85_right_finger_trans">
            <type>transmission_interface/SimpleTransmission</type>
            <joint name="${prefix}robotiq_85_right_finger_joint">
                <hardwareInterface>PositionJointInterface</hardwareInterface>
            </joint>
            <actuator name="${prefix}robotiq_85_right_finger_motor">
                <mechanicalReduction>1</mechanicalReduction>
            </actuator>
        </transmission-->
  <!--transmission name="${prefix}robotiq_85_left_finger_trans">
            <type>transmission_interface/SimpleTransmission</type>
            <joint name="${prefix}robotiq_85_left_finger_joint">
                <hardwareInterface>PositionJointInterface</hardwareInterface>
            </joint>
            <actuator name="${prefix}robotiq_85_left_finger_motor">
                <mechanicalReduction>1</mechanicalReduction>
            </actuator>
        </transmission-->
  <transmission name="robotiq_85_left_finger_tip_trans">
    <type>transmission_interface/SimpleTransmission</type>
    <joint name="robotiq_85_left_finger_tip_joint">
      <hardwareInterface>PositionJointInterface</hardwareInterface>
    </joint>
    <actuator name="robotiq_85_left_finger_tip_motor">
      <mechanicalReduction>1</mechanicalReduction>
    </actuator>
  </transmission>
  <transmission name="robotiq_85_right_finger_tip_trans">
    <type>transmission_interface/SimpleTransmission</type>
    <joint name="robotiq_85_right_finger_tip_joint">
      <hardwareInterface>PositionJointInterface</hardwareInterface>
    </joint>
    <actuator name="robotiq_85_right_finger_tip_motor">
      <mechanicalReduction>1</mechanicalReduction>
    </actuator>
  </transmission>
  <!-- nothing to do here at the moment -->
  <!--
        <xacro:robotiq_85_gripper prefix="${prefix}" parent="${prefix}ee_link" rotation="${-pi / 2.0} ${-pi / 2.0} 0" />

        <xacro:robotiq_85_gripper_transmission prefix="${prefix}" />
        <xacro:jaco_arm_gazebo prefix="${prefix}" />
        -->
  <joint name="jaco_base_joint_simplified" type="fixed">
    <parent link="jaco_base_link"/>
    <child link="jaco_base_link_simplified"/>
  </joint>
  <link name="jaco_base_link_simplified">
    <collision>
      <geometry>
        <box size="0.09 0.09 0.32"/>
      </geometry>
      <origin rpy="0 0 0" xyz="0 0 0.16"/>
    </collision>
  </link>
  <joint name="jaco_shoulder_lift_joint_simplified" type="fixed">
    <parent link="jaco_upper_arm_link"/>
    <child link="jaco_upper_arm_link_simplified"/>
  </joint>
  <link name="jaco_upper_arm_link_simplified">
    <collision>
      <geometry>
        <box size="0.46 0.09 0.05"/>
      </geometry>
      <origin rpy="0 0 0" xyz="0.23 0 -.025"/>
    </collision>
  </link>
  <joint name="jaco_elbow_joint_simplified" type="fixed">
    <parent link="jaco_forearm_link"/>
    <child link="jaco_forearm_link_simplified"/>
  </joint>
  <link name="jaco_forearm_link_simplified">
    <collision>
      <geometry>
        <box size="0.255 0.09 0.07"/>
      </geometry>
      <origin rpy="0 0 0" xyz="0.085 0 0.0"/>
    </collision>
  </link>
  <joint name="jaco_wrist_1_joint_simplified" type="fixed">
    <parent link="jaco_wrist_1_link"/>
    <child link="jaco_wrist_1_link_simplified"/>
  </joint>
  <link name="jaco_wrist_1_link_simplified">
    <collision>
      <geometry>
        <box size="0.095 0.09 0.09"/>
      </geometry>
      <origin rpy="0 0 0" xyz="0.0125 0 0.045"/>
    </collision>
  </link>
  <joint name="jaco_wrist_2_joint_simplified" type="fixed">
    <parent link="jaco_wrist_2_link"/>
    <child link="jaco_wrist_2_link_simplified"/>
  </joint>
  <link name="jaco_wrist_2_link_simplified">
    <collision>
      <geometry>
        <box size="0.095 0.09 0.09"/>
      </geometry>
      <origin rpy="0 0.523598775598 0" xyz="-0.005 0 0.075"/>
    </collision>
  </link>
  <joint name="jaco_wrist_3_joint_simplified" type="fixed">
    <parent link="jaco_wrist_3_link"/>
    <child link="jaco_wrist_3_link_simplified"/>
  </joint>
  <link name="jaco_wrist_3_link_simplified">
    <collision>
      <geometry>
        <box size="0.15 0.09 0.22"/>
      </geometry>
      <origin rpy="0 0 0" xyz="0 0 0.14"/>
    </collision>
  </link>
  <joint name="jaco_ee_link_nimbus_ee_link_joint" type="fixed">
    <parent link="jaco_ee_link"/>
    <child link="nimbus_ee_link"/>
    <origin rpy="0 -1.57079632679 0" xyz="0 0 0"/>
  </joint>
  <link name="nimbus_ee_link"/>
  <joint name="table_base_link_sensor_frame_center_link_joint" type="fixed">
    <parent link="table_base_link"/>
    <child link="sensor_frame_center_link"/>
    <origin rpy="0 0 0" xyz="0 0.0508 0"/>
  </joint>
  <link name="sensor_frame_center_link"/>
  <joint name="sensor_frame_center_link_sensor_frame_left_strut_link_joint" type="fixed">
    <parent link="sensor_frame_center_link"/>
    <child link="sensor_frame_left_strut_link"/>
    <origin rpy="0 0 0" xyz="-0.8397875 0 0"/>
  </joint>
  <link name="sensor_frame_left_strut_link">
    <visual>
      <geometry>
        <box size="0.0254 0.0508 1.2192"/>
      </geometry>
      <origin rpy="0 0 0" xyz="0 0 0.6096"/>
      <material name="light-gray">
        <color rgba="0.4 0.4 0.4 1"/>
      </material>
    </visual>
    <collision>
      <geometry>
        <box size="0.0508 0.0762 1.2192"/>
      </geometry>
      <origin rpy="0 0 0" xyz="0 0 0.6096"/>
    </collision>
  </link>
  <joint name="sensor_frame_left_strut_link_sensor_frame_left_bracket_left_foot_link_joint" type="fixed">
    <parent link="sensor_frame_left_strut_link"/>
    <child link="sensor_frame_left_bracket_left_foot_link"/>
    <origin rpy="0 0 0" xyz="-0.0381 0 0"/>
  </joint>
  <link name="sensor_frame_left_bracket_left_foot_link">
    <visual>
      <geometry>
        <box size="0.0508 0.0508 0.015875"/>
      </geometry>
      <origin rpy="0 0 0" xyz="0 0 0.0079375"/>
      <material name="light-gray"/>
    </visual>
    <collision>
      <geometry>
        <box size="0.0708 0.0708 0.06"/>
      </geometry>
      <origin rpy="0 0 0" xyz="0 0 0.03"/>
    </collision>
  </link>
  <joint name="sensor_frame_left_bracket_left_foot_link_sensor_frame_left_bracket_left_side_link_joint" type="fixed">
    <parent link="sensor_frame_left_bracket_left_foot_link"/>
    <child link="sensor_frame_left_bracket_left_side_link"/>
    <origin rpy="0 0 0" xyz="0.01905 0 0"/>
  </joint>
  <link name="sensor_frame_left_bracket_left_side_link">
    <visual>
      <geometry>
        <box size="0.0127 0.0508 0.127"/>
      </geometry>
      <origin rpy="0 0 0" xyz="0 0 0.0635"/>
      <material name="light-gray"/>
    </visual>
    <collision>
      <geometry>
        <box size="0.0127 0.0508 0.127"/>
      </geometry>
      <origin rpy="0 0 0" xyz="0 0 0.0635"/>
    </collision>
  </link>
  <joint name="sensor_frame_left_strut_link_sensor_frame_left_bracket_right_foot_link_joint" type="fixed">
    <parent link="sensor_frame_left_strut_link"/>
    <child link="sensor_frame_left_bracket_right_foot_link"/>
    <origin rpy="0 0 0" xyz="0.0381 0 0"/>
  </joint>
  <link name="sensor_frame_left_bracket_right_foot_link">
    <visual>
      <geometry>
        <box size="0.0508 0.0508 0.015875"/>
      </geometry>
      <origin rpy="0 0 0" xyz="0 0 0.0079375"/>
      <material name="light-gray"/>
    </visual>
    <collision>
      <geometry>
        <box size="0.0708 0.0708 0.06"/>
      </geometry>
      <origin rpy="0 0 0" xyz="0 0 0.03"/>
    </collision>
  </link>
  <joint name="sensor_frame_left_bracket_right_foot_link_sensor_frame_left_bracket_right_side_link_joint" type="fixed">
    <parent link="sensor_frame_left_bracket_right_foot_link"/>
    <child link="sensor_frame_left_bracket_right_side_link"/>
    <origin rpy="0 0 0" xyz="-0.01905 0 0"/>
  </joint>
  <link name="sensor_frame_left_bracket_right_side_link">
    <visual>
      <geometry>
        <box size="0.0127 0.0508 0.127"/>
      </geometry>
      <origin rpy="0 0 0" xyz="0 0 0.0635"/>
      <material name="light-gray"/>
    </visual>
    <collision>
      <geometry>
        <box size="0.0127 0.0508 0.127"/>
      </geometry>
      <origin rpy="0 0 0" xyz="0 0 0.0635"/>
    </collision>
  </link>
  <joint name="sensor_frame_center_link_sensor_frame_right_strut_link_joint" type="fixed">
    <parent link="sensor_frame_center_link"/>
    <child link="sensor_frame_right_strut_link"/>
    <origin rpy="0 0 0" xyz="0.8397875 0 0"/>
  </joint>
  <link name="sensor_frame_right_strut_link">
    <visual>
      <geometry>
        <box size="0.0254 0.0508 1.2192"/>
      </geometry>
      <origin rpy="0 0 0" xyz="0 0 0.6096"/>
      <material name="light-gray"/>
    </visual>
    <collision>
      <geometry>
        <box size="0.0508 0.0762 1.2192"/>
      </geometry>
      <origin rpy="0 0 0" xyz="0 0 0.6096"/>
    </collision>
  </link>
  <joint name="sensor_frame_right_strut_link_sensor_frame_right_bracket_left_foot_link_joint" type="fixed">
    <parent link="sensor_frame_right_strut_link"/>
    <child link="sensor_frame_right_bracket_left_foot_link"/>
    <origin rpy="0 0 0" xyz="-0.0381 0 0"/>
  </joint>
  <link name="sensor_frame_right_bracket_left_foot_link">
    <visual>
      <geometry>
        <box size="0.0508 0.0508 0.015875"/>
      </geometry>
      <origin rpy="0 0 0" xyz="0 0 0.0079375"/>
      <material name="light-gray"/>
    </visual>
    <collision>
      <geometry>
        <box size="0.0708 0.0708 0.06"/>
      </geometry>
      <origin rpy="0 0 0" xyz="0 0 0.03"/>
    </collision>
  </link>
  <joint name="sensor_frame_right_bracket_left_foot_link_sensor_frame_right_bracket_left_side_link_joint" type="fixed">
    <parent link="sensor_frame_right_bracket_left_foot_link"/>
    <child link="sensor_frame_right_bracket_left_side_link"/>
    <origin rpy="0 0 0" xyz="0.01905 0 0"/>
  </joint>
  <link name="sensor_frame_right_bracket_left_side_link">
    <visual>
      <geometry>
        <box size="0.0127 0.0508 0.127"/>
      </geometry>
      <origin rpy="0 0 0" xyz="0 0 0.0635"/>
      <material name="light-gray"/>
    </visual>
    <collision>
      <geometry>
        <box size="0.0127 0.0508 0.127"/>
      </geometry>
      <origin rpy="0 0 0" xyz="0 0 0.0635"/>
    </collision>
  </link>
  <joint name="sensor_frame_right_strut_link_sensor_frame_right_bracket_right_foot_link_joint" type="fixed">
    <parent link="sensor_frame_right_strut_link"/>
    <child link="sensor_frame_right_bracket_right_foot_link"/>
    <origin rpy="0 0 0" xyz="0.0381 0 0"/>
  </joint>
  <link name="sensor_frame_right_bracket_right_foot_link">
    <visual>
      <geometry>
        <box size="0.0508 0.0508 0.015875"/>
      </geometry>
      <origin rpy="0 0 0" xyz="0 0 0.0079375"/>
      <material name="light-gray"/>
    </visual>
    <collision>
      <geometry>
        <box size="0.0708 0.0708 0.06"/>
      </geometry>
      <origin rpy="0 0 0" xyz="0 0 0.03"/>
    </collision>
  </link>
  <joint name="sensor_frame_right_bracket_right_foot_link_sensor_frame_right_bracket_right_side_link_joint" type="fixed">
    <parent link="sensor_frame_right_bracket_right_foot_link"/>
    <child link="sensor_frame_right_bracket_right_side_link"/>
    <origin rpy="0 0 0" xyz="-0.01905 0 0"/>
  </joint>
  <link name="sensor_frame_right_bracket_right_side_link">
    <visual>
      <geometry>
        <box size="0.0127 0.0508 0.127"/>
      </geometry>
      <origin rpy="0 0 0" xyz="0 0 0.0635"/>
      <material name="light-gray"/>
    </visual>
    <collision>
      <geometry>
        <box size="0.0127 0.0508 0.127"/>
      </geometry>
      <origin rpy="0 0 0" xyz="0 0 0.0635"/>
    </collision>
  </link>
  <joint name="sensor_frame_center_link_sensor_frame_top_beam_link_joint" type="fixed">
    <parent link="sensor_frame_center_link"/>
    <child link="sensor_frame_top_beam_link"/>
    <origin rpy="0 0 0" xyz="0 0 1.2319"/>
  </joint>
  <link name="sensor_frame_top_beam_link">
    <visual>
      <geometry>
        <box size="1.8288 0.0508 0.0254"/>
      </geometry>
      <material name="light-gray"/>
    </visual>
    <collision>
      <geometry>
        <box size="1.8888 0.1108 0.0854"/>
      </geometry>
    </collision>
  </link>
  <joint name="sensor_frame_top_beam_link_sensor_frame_camera_strut_link_joint" type="fixed">
    <parent link="sensor_frame_top_beam_link"/>
    <child link="sensor_frame_camera_strut_link"/>
    <origin rpy="-0.785398163397 0 0" xyz="-0.0254 0.0254 0.0127"/>
  </joint>
  <link name="sensor_frame_camera_strut_link">
    <visual>
      <geometry>
        <box size="0.0508 0.1524 0.0254"/>
      </geometry>
      <origin rpy="0 0 0" xyz="0 0.0762 -0.0127"/>
      <material name="light-gray"/>
    </visual>
    <collision>
      <geometry>
        <box size="0.0808 0.1824 0.0554"/>
      </geometry>
      <origin rpy="0 0 0" xyz="0 0.0762 -0.0127"/>
    </collision>
  </link>
  <joint name="sensor_frame_camera_strut_link_sensor_frame_camera_plate_link_joint" type="fixed">
    <parent link="sensor_frame_camera_strut_link"/>
    <child link="sensor_frame_camera_plate_link"/>
    <origin rpy="0 0 0" xyz="0 0.1016 0.003175"/>
  </joint>
  <link name="sensor_frame_camera_plate_link">
    <visual>
      <geometry>
        <box size="0.1016 0.1016 0.00635"/>
      </geometry>
      <material name="light-gray"/>
    </visual>
    <collision>
      <geometry>
        <box size="0.1316 0.1316 0.01905"/>
      </geometry>
    </collision>
  </link>
  <joint name="sensor_frame_camera_plate_link_sensor_frame_sensor_link_joint" type="fixed">
    <parent link="sensor_frame_camera_plate_link"/>
    <child link="sensor_frame_sensor_link"/>
    <origin rpy="0 0 0" xyz="0.041275 0.041275 0.003175"/>
  </joint>
  <link name="sensor_frame_sensor_link"/>
  <joint name="sensor_frame_sensor_link_kinect2_mounting_plate_link_joint" type="fixed">
    <parent link="sensor_frame_sensor_link"/>
    <child link="kinect2_mounting_plate_link"/>
    <origin rpy="0 0 -0.018" xyz="0.009 -0.005 -0.011"/>
  </joint>
  <link name="kinect2_mounting_plate_link">
    <visual>
      <geometry>
        <box size="0.1143 0.06985 0.009525"/>
      </geometry>
      <origin rpy="0 0 0" xyz="0 -0.0127 0.0047625"/>
      <material name="grey">
        <color rgba="0.2 0.2 0.2 1"/>
      </material>
    </visual>
    <collision>
      <geometry>
        <box size="0.1143 0.06985 0.009525"/>
      </geometry>
      <origin rpy="0 0 0" xyz="0 -0.0127 0.0047625"/>
    </collision>
  </link>
  <joint name="kinect2_mounting_plate_link_kinect2_mic_bar_link_joint" type="fixed">
    <parent link="kinect2_mounting_plate_link"/>
    <child link="kinect2_mic_bar_link"/>
    <origin rpy="0 0 0" xyz="0 0.0254 0.00873125"/>
  </joint>
  <link name="kinect2_mic_bar_link">
    <visual>
      <geometry>
        <box size="0.250825 0.015875 0.0174625"/>
      </geometry>
      <material name="grey"/>
    </visual>
    <collision>
      <geometry>
        <box size="0.310825 0.075875 0.0774625"/>
      </geometry>
    </collision>
  </link>
  <joint name="kinect2_mic_bar_link_kinect2_tilt_base_link_joint" type="fixed">
    <parent link="kinect2_mic_bar_link"/>
    <child link="kinect2_tilt_base_link"/>
    <origin rpy="0 0 0" xyz="0 -0.003571875 0.01825625"/>
  </joint>
  <link name="kinect2_tilt_base_link" type="fixed">
    <visual>
      <geometry>
        <box size="0.1143 0.00714375 0.009525"/>
      </geometry>
      <origin xyz="0 0 -0.0047625"/>
      <material name="grey"/>
    </visual>
    <collision>
      <geometry>
        <box size="0.1143 0.00714375 0.009525"/>
      </geometry>
      <origin xyz="0 0 0.0047625"/>
    </collision>
  </link>
  <joint name="kinect2_tilt_base_link_kinect2_tilt_link_joint" type="fixed">
    <parent link="kinect2_tilt_base_link"/>
    <child link="kinect2_tilt_link"/>
    <origin rpy="-0.536 0 0" xyz="0 0 0"/>
  </joint>
  <link name="kinect2_tilt_link"/>
  <joint name="kinect2_tilt_link_kinect2_structure_link_joint" type="fixed">
    <parent link="kinect2_tilt_link"/>
    <child link="kinect2_structure_link"/>
    <origin rpy="0 0 0" xyz="0.0968375 0 0.022225"/>
  </joint>
  <link name="kinect2_structure_link">
    <visual>
      <geometry>
        <box size="0.250825 0.06985 0.04445"/>
      </geometry>
      <origin xyz="-0.0968375 -0.02778125 0"/>
      <material name="grey"/>
    </visual>
    <collision>
      <geometry>
        <box size="0.310825 0.12985 0.10445"/>
      </geometry>
      <origin xyz="-0.0968375 -0.02778125 0"/>
    </collision>
  </link>
  <joint name="kinect2_structure_link_kinect2_link_joint" type="fixed">
    <parent link="kinect2_structure_link"/>
    <child link="kinect2_link"/>
    <origin rpy="-1.57079632679 0 0" xyz="0 0 0"/>
  </joint>
  <link name="kinect2_link"/>
</robot>

